2018-10-22 12:11:25,038 1 INFO odoo odoo.sql_db: Connection to the database failed
2018-10-22 12:11:25,100 1 WARNING ? odoo.addons.base.ir.ir_cron: Exception in cron:
Traceback (most recent call last):
  File "/usr/lib/python3/dist-packages/odoo/addons/base/ir/ir_cron.py", line 258, in _acquire_job
    cls._process_jobs(db_name)
  File "/usr/lib/python3/dist-packages/odoo/addons/base/ir/ir_cron.py", line 168, in _process_jobs
    with db.cursor() as cr:
  File "/usr/lib/python3/dist-packages/odoo/sql_db.py", line 634, in cursor
    return Cursor(self.__pool, self.dbname, self.dsn, serialized=serialized)
  File "/usr/lib/python3/dist-packages/odoo/sql_db.py", line 178, in __init__
    self._cnx = pool.borrow(dsn)
  File "/usr/lib/python3/dist-packages/odoo/sql_db.py", line 517, in _locked
    return fun(self, *args, **kwargs)
  File "/usr/lib/python3/dist-packages/odoo/sql_db.py", line 585, in borrow
    **connection_info)
  File "/usr/lib/python3/dist-packages/psycopg2/__init__.py", line 164, in connect
    conn = _connect(dsn, connection_factory=connection_factory, async=async)
psycopg2.OperationalError: FATAL:  database "odoo" does not exist

